#VRML_SIM R2023b utf8

EXTERNPROTO "https://raw.githubusercontent.com/cyberbotics/webots/R2023b/projects/objects/floors/protos/Floor.proto"
EXTERNPROTO "https://raw.githubusercontent.com/cyberbotics/webots/R2023b/projects/objects/backgrounds/protos/TexturedBackground.proto"
EXTERNPROTO "https://raw.githubusercontent.com/cyberbotics/webots/R2023b/projects/objects/backgrounds/protos/TexturedBackgroundLight.proto"
EXTERNPROTO "https://raw.githubusercontent.com/cyberbotics/webots/R2023b/projects/objects/factory/containers/protos/WoodenBox.proto"
EXTERNPROTO "https://raw.githubusercontent.com/cyberbotics/webots/R2023b/projects/appearances/protos/GlossyPaint.proto"

WorldInfo {
  window "generic_window"
  basicTimeStep 16
  coordinateSystem "NUE"
  contactProperties [
    ContactProperties {
      coulombFriction [
        0.5
      ]
    }
  ]
}
Viewpoint {
  orientation -0.31856529243517784 -0.5750750351801001 -0.7535282731047963 2.161349593958714
  position 1.4084486967897583 0.7835222039992413 -1.310522722523704
  follow "floor"
}
TexturedBackground {
}
TexturedBackgroundLight {
}
Floor {
  rotation 1 0 0 -1.5707996938995747
  size 3 3
}
WoodenBox {
  hidden linearVelocity_0 -6.992811181141166e-18 -2.030122102171715e-16 -5.780476852356826e-11
  hidden angularVelocity_0 3.806478941557129e-16 3.732365978781341e-17 3.8064789415719577e-16
  translation 0.48030150349139195 0.049865090827255716 0.7219338881995085
  rotation -2.7326184323547686e-05 -0.9999999996252148 1.6881894574439568e-06 0.1234015397098371
  size 0.1 0.1 0.1
  mass 0.7
}
Solid {
  translation 0.7571721068791285 0.04984159286158548 -0.4297872612492281
  rotation -4.7110730113285574e-06 0.9999999999874768 -1.6888539894677959e-06 0.6884293753964006
  children [
    DEF BOX_SHAPE Shape {
      appearance PBRAppearance {
        baseColorMap ImageTexture {
          url [
            "https://raw.githubusercontent.com/cyberbotics/webots/R2023b/projects/objects/factory/containers/protos/textures/wooden_box_base_color.jpg"
          ]
        }
        roughnessMap ImageTexture {
          url [
            "https://raw.githubusercontent.com/cyberbotics/webots/R2023b/projects/objects/factory/containers/protos/textures/wooden_box_roughness.jpg"
          ]
        }
        metalness 0
        normalMap ImageTexture {
          url [
            "https://raw.githubusercontent.com/cyberbotics/webots/R2023b/projects/objects/factory/containers/protos/textures/wooden_box_normal.jpg"
          ]
        }
        occlusionMap ImageTexture {
          url [
            "https://raw.githubusercontent.com/cyberbotics/webots/R2023b/projects/objects/factory/containers/protos/textures/wooden_box_occlusion.jpg"
          ]
        }
      }
      geometry Box {
        size 0.1 0.1 0.1
      }
    }
  ]
  name "wooden box(2)"
  model "wooden box"
  boundingObject USE BOX_SHAPE
  physics Physics {
    density -1
    mass 0.8
  }
  recognitionColors [
    0 0 0
  ]
  linearVelocity 2.8430520320060904e-17 -2.1316282072803012e-16 -6.60626074116687e-11
  angularVelocity 3.3306690738733713e-16 -1.7995903178687304e-17 -3.5388358909926914e-16
}
WoodenBox {
  hidden linearVelocity_0 3.9344098996547255e-16 -2.2737367544323197e-16 -4.1289167638695145e-11
  hidden angularVelocity_0 -1.0658141036387512e-15 -8.700976544078042e-17 -8.393286066166219e-15
  translation -0.7747128031244316 0.04990252879272683 0.18674573661154048
  rotation 0.7059497847366195 0.7059495918156801 -0.05718457174444234 -3.0273526791405394
  name "wooden box(1)"
  size 0.1 0.1 0.1
  mass 0.5
}
DEF WALL_1 Solid {
  translation 1.49 0.05 0
  children [
    DEF WALL_SHAPE Shape {
      appearance PBRAppearance {
        baseColor 0.203922 0.396078 0.643137
        roughness 0.5
        metalness 0
      }
      geometry Box {
        size 0.02 0.2 3
      }
    }
  ]
  name "wall_1"
  boundingObject USE WALL_SHAPE
}
DEF WALL_2 Solid {
  translation -1.49 0.05 0
  children [
    USE WALL_SHAPE
  ]
  name "wall_2"
  boundingObject USE WALL_SHAPE
}
DEF WALL_3 Solid {
  translation 3.67316e-06 0.05 1.5
  rotation 0 1 0 1.5708
  children [
    USE WALL_SHAPE
  ]
  name "wall_3"
  boundingObject USE WALL_SHAPE
}
DEF WALL_4 Solid {
  translation -3.63633e-06 0.05 -1.49
  rotation 0 1 0 1.5708
  children [
    USE WALL_SHAPE
  ]
  name "wall_4"
  boundingObject USE WALL_SHAPE
}
Robot {
  translation 0.5749993725645045 0.03986090908568193 0.18400382336369692
  rotation -2.0458465494694694e-06 0.9999999999816495 -5.702227286355215e-06 -1.6873960050554668
  children [
    DEF linear_joint SliderJoint {
      jointParameters JointParameters {
        position -1.734723475976807e-18
        axis 0 1 0
        minStop 0.06
        maxStop 0.13
      }
      device [
        DEF linear LinearMotor {
          name "linear"
        }
      ]
      endPoint DEF linear_joint Solid {
        translation 0 0.06000000000000001 0.09
        children [
          Shape {
            appearance Appearance {
              material Material {
                diffuseColor 1 0.2 0
              }
              texture ImageTexture {
              }
            }
            geometry Box {
              size 0.02 0.02 0.15
            }
          }
          HingeJoint {
            jointParameters HingeJointParameters {
              position -9.71445146547012e-17
              axis 0 1 0
              anchor 0.01 0 0.076
            }
            device [
              RotationalMotor {
                name "rm"
              }
            ]
            endPoint Solid {
              translation 8.673617379884035e-18 0 0.08
              rotation 0 1 0 0
              children [
                Shape {
                  appearance Appearance {
                    material Material {
                      diffuseColor 0 0 1
                    }
                  }
                  geometry Cylinder {
                    height 0.03
                    radius 0.007
                  }
                }
                Camera {
                  rotation 1 0 0 -1.5707996938995747
                  name "camcam"
                  recognitionColors [
                    0 0 0
                  ]
                  width 640
                  height 640
                  recognition Recognition {
                    frameColor 0.9 1 1
                    frameThickness 3
                  }
                }
              ]
            }
          }
        ]
        name "solid(4)"
      }
    }
    HingeJoint {
      jointParameters HingeJointParameters {
        position 1001.0697290926024
        anchor 0.06 0 0.05
      }
      device [
        RotationalMotor {
          name "wheel1"
        }
      ]
      endPoint DEF WHEEL_1 Solid {
        translation 0.06 0 0.05
        rotation -0.22788559933653146 0.9466448659711104 0.22788517140342499 4.657582495712413
        children [
          DEF WHEEL Shape {
            appearance PBRAppearance {
              baseColor 0.45098 0.823529 0.0862745
              roughness 0.5
              metalness 0
            }
            geometry Cylinder {
              height 0.02
              radius 0.04
            }
          }
        ]
        boundingObject USE WHEEL
        physics DEF WHEEL_PH Physics {
        }
        linearVelocity -9.375998358458443e-14 -8.663188479508623e-17 -5.804811942896203e-11
        angularVelocity -7.239763724680459e-14 -1.319377547367297e-12 5.426631702858739e-13
      }
    }
    HingeJoint {
      jointParameters HingeJointParameters {
        position 1001.0331819261902
        anchor 0.06 0 -0.05
      }
      device [
        RotationalMotor {
          name "wheel3"
        }
      ]
      endPoint DEF WHEEL_3 Solid {
        translation 0.06 0 -0.05
        rotation -0.21135470631999154 0.9542843273544349 0.21135423033874565 4.665609778769796
        children [
          USE WHEEL
        ]
        name "solid(1)"
        boundingObject USE WHEEL
        physics USE WHEEL_PH
        linearVelocity -1.0768033036185602e-13 -2.8082964977261e-16 -5.7916280562398745e-11
        angularVelocity -6.476334184302087e-14 -1.3195499289113366e-12 5.434145463442209e-13
      }
    }
    HingeJoint {
      jointParameters HingeJointParameters {
        position 1108.8138420812302
        anchor -0.06 0 0.05
      }
      device [
        RotationalMotor {
          name "wheel2"
        }
      ]
      endPoint DEF WHEEL_2 Solid {
        translation -0.06 0 0.05
        rotation 0.5421180149172036 -0.6420400379843849 -0.542118665540341 2.0000774629522895
        children [
          USE WHEEL
        ]
        name "solid(2)"
        boundingObject USE WHEEL
        physics USE WHEEL_PH
        linearVelocity 6.538834533432014e-14 -5.253822937409447e-17 -5.8029046760511055e-11
        angularVelocity -5.737218513972291e-14 -1.3200912331375718e-12 5.313324892352354e-13
      }
    }
    HingeJoint {
      jointParameters HingeJointParameters {
        position 1108.7772951694692
        anchor -0.06 0 -0.05
      }
      device [
        RotationalMotor {
          name "wheel4"
        }
      ]
      endPoint DEF WHEEL_4 Solid {
        translation -0.06 0 -0.05
        rotation 0.5336898096874064 -0.6560104548750775 -0.5336904253688779 1.9804178561015886
        children [
          USE WHEEL
        ]
        name "solid(3)"
        boundingObject USE WHEEL
        physics USE WHEEL_PH
        linearVelocity 5.0087994940650554e-14 -1.0722718559681085e-16 -5.789853624180275e-11
        angularVelocity -5.817326136756054e-14 -1.3199170590174545e-12 5.313754803263921e-13
      }
    }
    DEF BODY Shape {
      appearance PBRAppearance {
        baseColor 0.643137 0 0
        roughness 0.5
        metalness 0
      }
      geometry Box {
        size 0.1 0.05 0.2
      }
    }
    DistanceSensor {
      translation 0.025 0 0.1
      rotation 0 1 0 -1.2708
      children [
        DEF DS_SHAPE Shape {
          appearance PBRAppearance {
            baseColor 0.12549 0.290196 0.529412
          }
          geometry Box {
            size 0.01 0.01 0.01
          }
        }
      ]
      name "ds_left"
      boundingObject USE DS_SHAPE
      physics Physics {
      }
    }
    DistanceSensor {
      translation -0.025 0 0.1
      rotation 0 1 0 -1.8708
      children [
        USE DS_SHAPE
      ]
      name "ds_right"
      boundingObject USE DS_SHAPE
      physics Physics {
      }
    }
    Solid {
      translation 0 0.11 0.07
      children [
        Shape {
          geometry Box {
            size 0.03 0.18 0.02
          }
        }
      ]
      name "rack"
      boundingObject DEF g1 Group {
      }
    }
  ]
  name "original_4_wheels_robot"
  boundingObject USE BODY
  physics Physics {
  }
  controller "keyboard"
  linearVelocity -2.3885215196618248e-14 -2.2691983577168866e-16 -5.7973418368591e-11
  angularVelocity -1.0589514966739815e-15 -1.3199868755553156e-12 2.302626920018762e-15
}
Solid {
  translation -0.24003985677284184 0.09082953272967202 -0.4694899436065513
  rotation 0.030259742158979624 -0.03052338613338064 0.9990759084791427 2.3528940747853673
  children [
    DEF GO Group {
      children [
        Pose {
          translation 0 0 -0.12
          children [
            Shape {
              appearance Appearance {
                material Material {
                  diffuseColor 0 1 1
                  emissiveColor 0 1 0.2
                  shininess 1
                  specularColor 0 1 1
                }
                texture ImageTexture {
                }
              }
              geometry Sphere {
                radius 0.1
              }
            }
          ]
        }
        Pose {
          translation 0 0 0.15
          children [
            Shape {
              appearance GlossyPaint {
                baseColor 1 0.1 1
              }
              geometry Sphere {
                radius 0.08
              }
            }
          ]
        }
        Shape {
          appearance PBRAppearance {
          }
          geometry Cylinder {
            height 0.4
            radius 0.02
          }
        }
      ]
    }
  ]
  boundingObject USE GO
  physics Physics {
    mass 0.69
    damping Damping {
    }
  }
  recognitionColors [
    1 0 0
  ]
  linearVelocity 5.965699734044636e-07 -6.063776082695682e-14 -1.799765637714298e-08
  angularVelocity -1.9215443588140452e-07 -3.983595164209789e-09 -6.409801827337669e-06
}
