#VRML_SIM R2023b utf8

EXTERNPROTO "https://raw.githubusercontent.com/cyberbotics/webots/R2023b/projects/objects/floors/protos/Floor.proto"
EXTERNPROTO "https://raw.githubusercontent.com/cyberbotics/webots/R2023b/projects/objects/backgrounds/protos/TexturedBackground.proto"
EXTERNPROTO "https://raw.githubusercontent.com/cyberbotics/webots/R2023b/projects/objects/backgrounds/protos/TexturedBackgroundLight.proto"
EXTERNPROTO "https://raw.githubusercontent.com/cyberbotics/webots/R2023b/projects/objects/factory/containers/protos/WoodenBox.proto"
EXTERNPROTO "https://raw.githubusercontent.com/cyberbotics/webots/R2023b/projects/appearances/protos/GlossyPaint.proto"

WorldInfo {
  window "generic_window"
  basicTimeStep 16
  coordinateSystem "NUE"
  contactProperties [
    ContactProperties {
      coulombFriction [
        0.5
      ]
    }
  ]
}
Viewpoint {
  orientation 0.7069097530836932 -0.11287411396257335 0.6982392393673645 4.65695159280512
  position -0.947764816980158 1.2147806406082977 -1.0065808356967278
}
TexturedBackground {
}
TexturedBackgroundLight {
}
Floor {
  rotation 1 0 0 -1.5707996938995747
  size 3 3
}
WoodenBox {
  hidden linearVelocity_0 9.54965757544058e-18 -2.8421709430404013e-16 -5.780525439818158e-11
  hidden angularVelocity_0 -9.32587340685278e-15 -2.764062114421585e-17 -5.709718412357945e-16
  translation 0.48030150349139195 0.04986509082732686 0.7219339093289521
  rotation -2.732618431891112e-05 -0.9999999996252149 1.6881894568109674e-06 0.12340153970983721
  size 0.1 0.1 0.1
  mass 0.7
}
WoodenBox {
  hidden linearVelocity_0 -9.769550363118969e-18 -2.1316282072803007e-16 -6.60632062038061e-11
  hidden angularVelocity_0 -1.2989609388114338e-14 8.76810125817228e-17 2.081668171172165e-16
  translation 0.7571721068791285 0.049841592861695275 -0.4297872286425681
  rotation -4.7110730102088595e-06 0.9999999999874768 -1.6888539890697401e-06 0.6884293753964006
  name "wooden box(2)"
  size 0.1 0.1 0.1
  mass 0.8
}
WoodenBox {
  hidden linearVelocity_0 2.9877914243170087e-16 -1.4210854715202006e-16 -4.128936782391405e-11
  hidden angularVelocity_0 -5.0626169922906075e-15 -1.780634355784052e-16 -6.128431095930721e-15
  translation -0.7747128031244316 0.04990252879277762 0.186745751703685
  rotation 0.7059497847366196 0.7059495918156798 -0.05718457174444234 -3.027352679140539
  name "wooden box(1)"
  size 0.1 0.1 0.1
  mass 0.5
}
DEF WALL_1 Solid {
  translation 1.49 0.05 0
  children [
    DEF WALL_SHAPE Shape {
      appearance PBRAppearance {
        baseColor 0.203922 0.396078 0.643137
        roughness 0.5
        metalness 0
      }
      geometry Box {
        size 0.02 0.2 3
      }
    }
  ]
  name "wall_1"
  boundingObject USE WALL_SHAPE
}
DEF WALL_2 Solid {
  translation -1.49 0.05 0
  children [
    USE WALL_SHAPE
  ]
  name "wall_2"
  boundingObject USE WALL_SHAPE
}
DEF WALL_3 Solid {
  translation 3.67316e-06 0.05 1.5
  rotation 0 1 0 1.5708
  children [
    USE WALL_SHAPE
  ]
  name "wall_3"
  boundingObject USE WALL_SHAPE
}
DEF WALL_4 Solid {
  translation -3.63633e-06 0.05 -1.49
  rotation 0 1 0 1.5708
  children [
    USE WALL_SHAPE
  ]
  name "wall_4"
  boundingObject USE WALL_SHAPE
}
Robot {
  translation 0.0068525141594335285 0.03985933878567737 -0.28236124353998204
  rotation 2.420304608739782e-06 -0.999999999980997 5.6699154444146525e-06 1.5343423731065264
  children [
    DEF linear_joint SliderJoint {
      jointParameters JointParameters {
        position 0.02
        axis 0 1 0
        minStop 0.06
        maxStop 0.13
      }
      device [
        DEF linear LinearMotor {
          name "linear"
        }
      ]
      endPoint DEF linear_joint Solid {
        translation 0 0.08000000000000002 0.09
        children [
          Shape {
            appearance Appearance {
              material Material {
                diffuseColor 1 0.2 0
              }
              texture ImageTexture {
              }
            }
            geometry Box {
              size 0.02 0.02 0.15
            }
          }
          HingeJoint {
            jointParameters HingeJointParameters {
              position -0.4
              axis 0 1 0
              anchor 0.01 0 0.076
            }
            device [
              RotationalMotor {
                name "rm"
              }
            ]
            endPoint Solid {
              translation -0.0007682833092634497 0 0.07579006055292505
              rotation 0 -1 0 0.4
              children [
                Shape {
                  appearance Appearance {
                    material Material {
                      diffuseColor 0 0 1
                    }
                  }
                  geometry Cylinder {
                    height 0.03
                    radius 0.007
                  }
                }
                Camera {
                  rotation 1 0 0 -1.5707996938995747
                  name "camcam"
                }
              ]
            }
          }
        ]
        name "solid(4)"
      }
    }
    HingeJoint {
      jointParameters HingeJointParameters {
        position 960.3581160567621
        anchor 0.06 0 0.05
      }
      device [
        RotationalMotor {
          name "wheel1"
        }
      ]
      endPoint DEF WHEEL_1 Solid {
        translation 0.06 0 0.05
        rotation 0.6906866882320736 0.21424559378988076 -0.6906885870206859 3.5637029755223653
        children [
          DEF WHEEL Shape {
            appearance PBRAppearance {
              baseColor 0.45098 0.823529 0.0862745
              roughness 0.5
              metalness 0
            }
            geometry Cylinder {
              height 0.02
              radius 0.04
            }
          }
        ]
        boundingObject USE WHEEL
        physics DEF WHEEL_PH Physics {
        }
        linearVelocity -7.557813749642911e-14 -1.7183479294410147e-17 -5.8034484730994005e-11
        angularVelocity -8.705357596428373e-15 -1.3320265431727533e-12 -1.6132748672844286e-13
      }
    }
    HingeJoint {
      jointParameters HingeJointParameters {
        position 960.3215497715911
        anchor 0.06 0 -0.05
      }
      device [
        RotationalMotor {
          name "wheel3"
        }
      ]
      endPoint DEF WHEEL_3 Solid {
        translation 0.06 0 -0.05
        rotation 0.6926668449235434 0.201053887578548 -0.692668734846042 3.5384105106172195
        children [
          USE WHEEL
        ]
        name "solid(1)"
        boundingObject USE WHEEL
        physics USE WHEEL_PH
        linearVelocity -7.061384782533325e-14 -2.6471264920640685e-16 -5.7900949846398345e-11
        angularVelocity -4.9008124781023134e-15 -1.3321129824846416e-12 -1.6100719047533466e-13
      }
    }
    HingeJoint {
      jointParameters HingeJointParameters {
        position 1074.3217470164498
        anchor -0.06 0 0.05
      }
      device [
        RotationalMotor {
          name "wheel2"
        }
      ]
      endPoint DEF WHEEL_2 Solid {
        translation -0.06 0 0.05
        rotation 0.5961634094804341 0.5377508607631829 -0.5961654140799514 4.128372121454708
        children [
          USE WHEEL
        ]
        name "solid(2)"
        boundingObject USE WHEEL
        physics USE WHEEL_PH
        linearVelocity 8.400604446035122e-14 -5.399872874951141e-17 -5.8040715592059215e-11
        angularVelocity -6.570898906134166e-15 -1.3317719553869877e-12 -1.7376666572781705e-13
      }
    }
    HingeJoint {
      jointParameters HingeJointParameters {
        position 1074.2851817441817
        anchor -0.06 0 -0.05
      }
      device [
        RotationalMotor {
          name "wheel4"
        }
      ]
      endPoint DEF WHEEL_4 Solid {
        translation -0.06 0 -0.05
        rotation 0.6023817528257167 0.5237079644214009 -0.6023837579684647 4.106458834654664
        children [
          USE WHEEL
        ]
        name "solid(3)"
        boundingObject USE WHEEL
        physics USE WHEEL_PH
        linearVelocity 8.899001760410878e-14 -7.592846825099842e-16 -5.790654717855871e-11
        angularVelocity 1.9638725880439078e-15 -1.3316853106947028e-12 -1.7408221830811106e-13
      }
    }
    DEF BODY Shape {
      appearance PBRAppearance {
        baseColor 0.643137 0 0
        roughness 0.5
        metalness 0
      }
      geometry Box {
        size 0.1 0.05 0.2
      }
    }
    DistanceSensor {
      translation 0.025 0 0.1
      rotation 0 1 0 -1.2708
      children [
        DEF DS_SHAPE Shape {
          appearance PBRAppearance {
            baseColor 0.12549 0.290196 0.529412
          }
          geometry Box {
            size 0.01 0.01 0.01
          }
        }
      ]
      name "ds_left"
      boundingObject USE DS_SHAPE
      physics Physics {
      }
    }
    DistanceSensor {
      translation -0.025 0 0.1
      rotation 0 1 0 -1.8708
      children [
        USE DS_SHAPE
      ]
      name "ds_right"
      boundingObject USE DS_SHAPE
      physics Physics {
      }
    }
    Solid {
      translation 0 0.11 0.07
      children [
        Shape {
          geometry Box {
            size 0.03 0.18 0.02
          }
        }
      ]
      name "rack"
      boundingObject DEF g1 Group {
      }
    }
  ]
  name "original_4_wheels_robot"
  boundingObject USE BODY
  physics Physics {
  }
  controller "keyboard"
  linearVelocity 6.690277763841651e-15 -1.9855485630022757e-16 -5.7971925288513626e-11
  angularVelocity 4.8483102157078315e-15 -1.3324649343060218e-12 2.433031047848907e-15
}
Solid {
  translation -0.24016056926284957 0.09082953274200867 -0.46948628038302187
  rotation 0.03028030434260333 -0.030514630625004542 0.9990755529421881 2.354218931345192
  children [
    DEF GO Group {
      children [
        Pose {
          translation 0 0 -0.12
          children [
            Shape {
              appearance Appearance {
                material Material {
                  diffuseColor 0 1 1
                  emissiveColor 0 1 0.2
                  shininess 1
                  specularColor 0 1 1
                }
                texture ImageTexture {
                }
              }
              geometry Sphere {
                radius 0.1
              }
            }
          ]
        }
        Pose {
          translation 0 0 0.15
          children [
            Shape {
              appearance GlossyPaint {
                baseColor 1 0.1 1
              }
              geometry Sphere {
                radius 0.08
              }
            }
          ]
        }
        Shape {
          appearance PBRAppearance {
          }
          geometry Cylinder {
            height 0.4
            radius 0.02
          }
        }
      ]
    }
  ]
  boundingObject USE GO
  physics Physics {
    mass 0.69
    damping Damping {
    }
  }
  recognitionColors [
    0.9 0.5 0.6
  ]
  linearVelocity 3.4088198706036926e-08 -8.795551197359674e-14 -1.1390014169424795e-09
  angularVelocity -1.1018612493972009e-08 -2.280477654138798e-10 -3.6628285766059984e-07
}
